Workbook

Sheet Cover
B3: Yariverse Bank (fictional bank)
B6: Fixed Income Analytics · Bond Pricing & Risk Workbook
B11: Workbook Version | C11: 1.0
B12: Model Type | C12: Fixed Coupon Bond Valuation
B13: Classification | C13: Internal Use Only
B14: Business Unit | C14: Corporate & Investment Bank
B15: Desk | C15: Fixed Income · Rates Strategy
B16: Prepared by | C16: Yari
B17: Reviewed by | C17: VP / Associate
B19: DISCLAIMER: For educational/training purposes only (JPMorgan Forage). Does not constitute investment advice. Formula outputs depend on analyst inputs in yellow cells.
B23: Worksheet Guide
B24: Assumptions | C24: Bond terms and market inputs: yellow cells are editable
B25: Pricing | C25: Bond price, YTM, current yield, price vs par
B26: Cash Flows | C26: Full coupon schedule with discount factors and PV
B27: Risk Metrics | C27: Duration, modified duration, DV01, convexity, shock estimates
B28: Price-Yield | C28: 29-scenario price vs yield table
B29: Scenario Analysis | C29: Yield shock comparison: true reprice vs approximations
B31: Color Convention
B32: Sample | C32: Hardcoded input, analyst editable
B33: Sample | C33: Formula / calculated, don't overwrite
B34: Sample | C34: Cross-sheet link (green text)

Sheet Assumptions
A1: Yariverse bank | Fixed Income Analytics | Bond Assumptions
A2: ASSUMPTIONS : All yellow cells are analyst-editable inputs
B4: BOND TERMS
B5: Issuer / Bond Name | C5: Yariverse Bank 5.00% 2034
B6: Face / Par Value ($) | C6: 1000
B7: Annual Coupon Rate (%) | C7: 0.05
B8: Years to Maturity | C8: 10
B9: Coupon Frequency (p.a.) | C9: 2
B10: Settlement Date | C10: 2024-01-15
B11: Maturity Date | C11: 2034-01-15
B13: MARKET INPUTS
B14: Market Yield / YTM (annual %) | C14: 0.06
B15: Market Price Override (leave 0 to use yield) | C15: 0
B17: NAMED RANGE GUIDE
B18: FaceValue | C18: Assumptions!C6
B19: CouponRate | C19: Assumptions!C7
B20: Maturity | C20: Assumptions!C8
B21: Freq | C21: Assumptions!C9
B22: MarketYield | C22: Assumptions!C14

Sheet Pricing
A1: Yariverse Bank. | Fixed Income Analytics | Bond Pricing
A2: PRICING : Outputs driven by Assumptions tab
B4: LINKED INPUTS
B5: Face Value ($) | C5: =Assumptions!C6 -> 1000
B6: Annual Coupon Rate | C6: =Assumptions!C7 -> 0.05
B7: Years to Maturity | C7: =Assumptions!C8 -> 10
B8: Coupon Frequency (p.a.) | C8: =Assumptions!C9 -> 2
B9: Market Yield (annual) | C9: =Assumptions!C14 -> 0.06
B11: DERIVED QUANTITIES
B12: Number of Coupon Periods (N) | C12: =ROUND(Assumptions!C8*Assumptions!C9,0) -> 20
B13: Periodic Coupon ($) | C13: =Assumptions!C6*Assumptions!C7/Assumptions!C9 -> 25
B14: Periodic Yield (r = YTM/Freq) | C14: =Assumptions!C14/Assumptions!C9 -> 0.03
B16: BOND PRICE [P = C×(1–(1+r)^–N)/r + F×(1+r)^–N]
B17: PV of Coupon Annuity [C×(1–(1+r)^–N)/r] | C17: =C13*(1-(1+C14)^(-C12))/C14 -> 371.93687
B18: PV of Par at Maturity [F×(1+r)^–N] | C18: =Assumptions!C6*(1+C14)^(-C12) -> 553.67575
B19: CLEAN PRICE ($) | C19: =C17+C18 -> 925.61263
B21: PRICE ANALYSIS
B22: Price as % of Par | C22: =C19/Assumptions!C6 -> 0.92561263
B23: Dollar Premium (+) / Discount (–) | C23: =C19-Assumptions!C6 -> -74.387374
B24: Trading Status | C24: =IF(C19>Assumptions!C6,"PREMIUM",IF(C19<Assumptions!C6,"DISCOUNT","PAR")) -> DISCOUNT
B25: Annual Coupon Income ($) | C25: =Assumptions!C6*Assumptions!C7 -> 50
B26: Current Yield | C26: =Assumptions!C6*Assumptions!C7/C19 -> 0.054018278
B27: Simple Yield (approx. YTM proxy) | C27: =(Assumptions!C6*Assumptions!C7+((Assumptions!C6-C19)/Assumptions!C8))/((C19+Assumptions!C6)/2) -> 0.059657624

Sheet Cash Flows
A1: Yariverse Bank. | Fixed Income Analytics | Cash Flow Schedule
A2: CASH FLOW SCHEDULE: Period-by-period coupon strip with discounted PVs
B4: Period | C4: Time (yrs) | D4: Coupon ($) | E4: Principal ($) | F4: Total CF ($) | G4: Disc. Factor | H4: PV of CF ($) | I4: Cumul. PV ($)
B5: =IF(1<=ROUND(Assumptions!C8*Assumptions!C9,0),1,"") -> 1 | C5: =IF(1<=ROUND(Assumptions!C8*Assumptions!C9,0),1/Assumptions!C9,"") -> 0.5 | D5: =IF(1<=ROUND(Assumptions!C8*Assumptions!C9,0),Assumptions!C6*Assumptions!C7/Assumptions!C9,"") -> 25 | E5: =IF(1=ROUND(Assumptions!C8*Assumptions!C9,0),Assumptions!C6,IF(1<ROUND(Assumptions!C8*Assumptions!C9,0),0,"")) -> 0 | F5: =IF(1<=ROUND(Assumptions!C8*Assumptions!C9,0),D5+E5,"") -> 25 | G5: =IF(1<=ROUND(Assumptions!C8*Assumptions!C9,0),(1+Assumptions!C14/Assumptions!C9)^(-1),"") -> 0.97087379 | H5: =IF(1<=ROUND(Assumptions!C8*Assumptions!C9,0),F5*G5,"") -> 24.271845 | I5: =IF(1<=ROUND(Assumptions!C8*Assumptions!C9,0),IF(1=1,H5,I4+H5),"") -> 24.271845
B6: =IF(2<=ROUND(Assumptions!C8*Assumptions!C9,0),2,"") -> 2 | C6: =IF(2<=ROUND(Assumptions!C8*Assumptions!C9,0),2/Assumptions!C9,"") -> 1 | D6: =IF(2<=ROUND(Assumptions!C8*Assumptions!C9,0),Assumptions!C6*Assumptions!C7/Assumptions!C9,"") -> 25 | E6: =IF(2=ROUND(Assumptions!C8*Assumptions!C9,0),Assumptions!C6,IF(2<ROUND(Assumptions!C8*Assumptions!C9,0),0,"")) -> 0 | F6: =IF(2<=ROUND(Assumptions!C8*Assumptions!C9,0),D6+E6,"") -> 25 | G6: =IF(2<=ROUND(Assumptions!C8*Assumptions!C9,0),(1+Assumptions!C14/Assumptions!C9)^(-2),"") -> 0.94259591 | H6: =IF(2<=ROUND(Assumptions!C8*Assumptions!C9,0),F6*G6,"") -> 23.564898 | I6: =IF(2<=ROUND(Assumptions!C8*Assumptions!C9,0),IF(2=1,H6,I5+H6),"") -> 47.836742
B7: =IF(3<=ROUND(Assumptions!C8*Assumptions!C9,0),3,"") -> 3 | C7: =IF(3<=ROUND(Assumptions!C8*Assumptions!C9,0),3/Assumptions!C9,"") -> 1.5 | D7: =IF(3<=ROUND(Assumptions!C8*Assumptions!C9,0),Assumptions!C6*Assumptions!C7/Assumptions!C9,"") -> 25 | E7: =IF(3=ROUND(Assumptions!C8*Assumptions!C9,0),Assumptions!C6,IF(3<ROUND(Assumptions!C8*Assumptions!C9,0),0,"")) -> 0 | F7: =IF(3<=ROUND(Assumptions!C8*Assumptions!C9,0),D7+E7,"") -> 25 | G7: =IF(3<=ROUND(Assumptions!C8*Assumptions!C9,0),(1+Assumptions!C14/Assumptions!C9)^(-3),"") -> 0.91514166 | H7: =IF(3<=ROUND(Assumptions!C8*Assumptions!C9,0),F7*G7,"") -> 22.878541 | I7: =IF(3<=ROUND(Assumptions!C8*Assumptions!C9,0),IF(3=1,H7,I6+H7),"") -> 70.715284
B8: =IF(4<=ROUND(Assumptions!C8*Assumptions!C9,0),4,"") -> 4 | C8: =IF(4<=ROUND(Assumptions!C8*Assumptions!C9,0),4/Assumptions!C9,"") -> 2 | D8: =IF(4<=ROUND(Assumptions!C8*Assumptions!C9,0),Assumptions!C6*Assumptions!C7/Assumptions!C9,"") -> 25 | E8: =IF(4=ROUND(Assumptions!C8*Assumptions!C9,0),Assumptions!C6,IF(4<ROUND(Assumptions!C8*Assumptions!C9,0),0,"")) -> 0 | F8: =IF(4<=ROUND(Assumptions!C8*Assumptions!C9,0),D8+E8,"") -> 25 | G8: =IF(4<=ROUND(Assumptions!C8*Assumptions!C9,0),(1+Assumptions!C14/Assumptions!C9)^(-4),"") -> 0.88848705 | H8: =IF(4<=ROUND(Assumptions!C8*Assumptions!C9,0),F8*G8,"") -> 22.212176 | I8: =IF(4<=ROUND(Assumptions!C8*Assumptions!C9,0),IF(4=1,H8,I7+H8),"") -> 92.92746
B9: =IF(5<=ROUND(Assumptions!C8*Assumptions!C9,0),5,"") -> 5 | C9: =IF(5<=ROUND(Assumptions!C8*Assumptions!C9,0),5/Assumptions!C9,"") -> 2.5 | D9: =IF(5<=ROUND(Assumptions!C8*Assumptions!C9,0),Assumptions!C6*Assumptions!C7/Assumptions!C9,"") -> 25 | E9: =IF(5=ROUND(Assumptions!C8*Assumptions!C9,0),Assumptions!C6,IF(5<ROUND(Assumptions!C8*Assumptions!C9,0),0,"")) -> 0 | F9: =IF(5<=ROUND(Assumptions!C8*Assumptions!C9,0),D9+E9,"") -> 25 | G9: =IF(5<=ROUND(Assumptions!C8*Assumptions!C9,0),(1+Assumptions!C14/Assumptions!C9)^(-5),"") -> 0.86260878 | H9: =IF(5<=ROUND(Assumptions!C8*Assumptions!C9,0),F9*G9,"") -> 21.56522 | I9: =IF(5<=ROUND(Assumptions!C8*Assumptions!C9,0),IF(5=1,H9,I8+H9),"") -> 114.49268
B10: =IF(6<=ROUND(Assumptions!C8*Assumptions!C9,0),6,"") -> 6 | C10: =IF(6<=ROUND(Assumptions!C8*Assumptions!C9,0),6/Assumptions!C9,"") -> 3 | D10: =IF(6<=ROUND(Assumptions!C8*Assumptions!C9,0),Assumptions!C6*Assumptions!C7/Assumptions!C9,"") -> 25 | E10: =IF(6=ROUND(Assumptions!C8*Assumptions!C9,0),Assumptions!C6,IF(6<ROUND(Assumptions!C8*Assumptions!C9,0),0,"")) -> 0 | F10: =IF(6<=ROUND(Assumptions!C8*Assumptions!C9,0),D10+E10,"") -> 25 | G10: =IF(6<=ROUND(Assumptions!C8*Assumptions!C9,0),(1+Assumptions!C14/Assumptions!C9)^(-6),"") -> 0.83748426 | H10: =IF(6<=ROUND(Assumptions!C8*Assumptions!C9,0),F10*G10,"") -> 20.937106 | I10: =IF(6<=ROUND(Assumptions!C8*Assumptions!C9,0),IF(6=1,H10,I9+H10),"") -> 135.42979
B11: =IF(7<=ROUND(Assumptions!C8*Assumptions!C9,0),7,"") -> 7 | C11: =IF(7<=ROUND(Assumptions!C8*Assumptions!C9,0),7/Assumptions!C9,"") -> 3.5 | D11: =IF(7<=ROUND(Assumptions!C8*Assumptions!C9,0),Assumptions!C6*Assumptions!C7/Assumptions!C9,"") -> 25 | E11: =IF(7=ROUND(Assumptions!C8*Assumptions!C9,0),Assumptions!C6,IF(7<ROUND(Assumptions!C8*Assumptions!C9,0),0,"")) -> 0 | F11: =IF(7<=ROUND(Assumptions!C8*Assumptions!C9,0),D11+E11,"") -> 25 | G11: =IF(7<=ROUND(Assumptions!C8*Assumptions!C9,0),(1+Assumptions!C14/Assumptions!C9)^(-7),"") -> 0.81309151 | H11: =IF(7<=ROUND(Assumptions!C8*Assumptions!C9,0),F11*G11,"") -> 20.327288 | I11: =IF(7<=ROUND(Assumptions!C8*Assumptions!C9,0),IF(7=1,H11,I10+H11),"") -> 155.75707
B12: =IF(8<=ROUND(Assumptions!C8*Assumptions!C9,0),8,"") -> 8 | C12: =IF(8<=ROUND(Assumptions!C8*Assumptions!C9,0),8/Assumptions!C9,"") -> 4 | D12: =IF(8<=ROUND(Assumptions!C8*Assumptions!C9,0),Assumptions!C6*Assumptions!C7/Assumptions!C9,"") -> 25 | E12: =IF(8=ROUND(Assumptions!C8*Assumptions!C9,0),Assumptions!C6,IF(8<ROUND(Assumptions!C8*Assumptions!C9,0),0,"")) -> 0 | F12: =IF(8<=ROUND(Assumptions!C8*Assumptions!C9,0),D12+E12,"") -> 25 | G12: =IF(8<=ROUND(Assumptions!C8*Assumptions!C9,0),(1+Assumptions!C14/Assumptions!C9)^(-8),"") -> 0.78940923 | H12: =IF(8<=ROUND(Assumptions!C8*Assumptions!C9,0),F12*G12,"") -> 19.735231 | I12: =IF(8<=ROUND(Assumptions!C8*Assumptions!C9,0),IF(8=1,H12,I11+H12),"") -> 175.4923
B13: =IF(9<=ROUND(Assumptions!C8*Assumptions!C9,0),9,"") -> 9 | C13: =IF(9<=ROUND(Assumptions!C8*Assumptions!C9,0),9/Assumptions!C9,"") -> 4.5 | D13: =IF(9<=ROUND(Assumptions!C8*Assumptions!C9,0),Assumptions!C6*Assumptions!C7/Assumptions!C9,"") -> 25 | E13: =IF(9=ROUND(Assumptions!C8*Assumptions!C9,0),Assumptions!C6,IF(9<ROUND(Assumptions!C8*Assumptions!C9,0),0,"")) -> 0 | F13: =IF(9<=ROUND(Assumptions!C8*Assumptions!C9,0),D13+E13,"") -> 25 | G13: =IF(9<=ROUND(Assumptions!C8*Assumptions!C9,0),(1+Assumptions!C14/Assumptions!C9)^(-9),"") -> 0.76641673 | H13: =IF(9<=ROUND(Assumptions!C8*Assumptions!C9,0),F13*G13,"") -> 19.160418 | I13: =IF(9<=ROUND(Assumptions!C8*Assumptions!C9,0),IF(9=1,H13,I12+H13),"") -> 194.65272
B14: =IF(10<=ROUND(Assumptions!C8*Assumptions!C9,0),10,"") -> 10 | C14: =IF(10<=ROUND(Assumptions!C8*Assumptions!C9,0),10/Assumptions!C9,"") -> 5 | D14: =IF(10<=ROUND(Assumptions!C8*Assumptions!C9,0),Assumptions!C6*Assumptions!C7/Assumptions!C9,"") -> 25 | E14: =IF(10=ROUND(Assumptions!C8*Assumptions!C9,0),Assumptions!C6,IF(10<ROUND(Assumptions!C8*Assumptions!C9,0),0,"")) -> 0 | F14: =IF(10<=ROUND(Assumptions!C8*Assumptions!C9,0),D14+E14,"") -> 25 | G14: =IF(10<=ROUND(Assumptions!C8*Assumptions!C9,0),(1+Assumptions!C14/Assumptions!C9)^(-10),"") -> 0.74409391 | H14: =IF(10<=ROUND(Assumptions!C8*Assumptions!C9,0),F14*G14,"") -> 18.602348 | I14: =IF(10<=ROUND(Assumptions!C8*Assumptions!C9,0),IF(10=1,H14,I13+H14),"") -> 213.25507
B15: =IF(11<=ROUND(Assumptions!C8*Assumptions!C9,0),11,"") -> 11 | C15: =IF(11<=ROUND(Assumptions!C8*Assumptions!C9,0),11/Assumptions!C9,"") -> 5.5 | D15: =IF(11<=ROUND(Assumptions!C8*Assumptions!C9,0),Assumptions!C6*Assumptions!C7/Assumptions!C9,"") -> 25 | E15: =IF(11=ROUND(Assumptions!C8*Assumptions!C9,0),Assumptions!C6,IF(11<ROUND(Assumptions!C8*Assumptions!C9,0),0,"")) -> 0 | F15: =IF(11<=ROUND(Assumptions!C8*Assumptions!C9,0),D15+E15,"") -> 25 | G15: =IF(11<=ROUND(Assumptions!C8*Assumptions!C9,0),(1+Assumptions!C14/Assumptions!C9)^(-11),"") -> 0.72242128 | H15: =IF(11<=ROUND(Assumptions!C8*Assumptions!C9,0),F15*G15,"") -> 18.060532 | I15: =IF(11<=ROUND(Assumptions!C8*Assumptions!C9,0),IF(11=1,H15,I14+H15),"") -> 231.3156
B16: =IF(12<=ROUND(Assumptions!C8*Assumptions!C9,0),12,"") -> 12 | C16: =IF(12<=ROUND(Assumptions!C8*Assumptions!C9,0),12/Assumptions!C9,"") -> 6 | D16: =IF(12<=ROUND(Assumptions!C8*Assumptions!C9,0),Assumptions!C6*Assumptions!C7/Assumptions!C9,"") -> 25 | E16: =IF(12=ROUND(Assumptions!C8*Assumptions!C9,0),Assumptions!C6,IF(12<ROUND(Assumptions!C8*Assumptions!C9,0),0,"")) -> 0 | F16: =IF(12<=ROUND(Assumptions!C8*Assumptions!C9,0),D16+E16,"") -> 25 | G16: =IF(12<=ROUND(Assumptions!C8*Assumptions!C9,0),(1+Assumptions!C14/Assumptions!C9)^(-12),"") -> 0.70137988 | H16: =IF(12<=ROUND(Assumptions!C8*Assumptions!C9,0),F16*G16,"") -> 17.534497 | I16: =IF(12<=ROUND(Assumptions!C8*Assumptions!C9,0),IF(12=1,H16,I15+H16),"") -> 248.8501
B17: =IF(13<=ROUND(Assumptions!C8*Assumptions!C9,0),13,"") -> 13 | C17: =IF(13<=ROUND(Assumptions!C8*Assumptions!C9,0),13/Assumptions!C9,"") -> 6.5 | D17: =IF(13<=ROUND(Assumptions!C8*Assumptions!C9,0),Assumptions!C6*Assumptions!C7/Assumptions!C9,"") -> 25 | E17: =IF(13=ROUND(Assumptions!C8*Assumptions!C9,0),Assumptions!C6,IF(13<ROUND(Assumptions!C8*Assumptions!C9,0),0,"")) -> 0 | F17: =IF(13<=ROUND(Assumptions!C8*Assumptions!C9,0),D17+E17,"") -> 25 | G17: =IF(13<=ROUND(Assumptions!C8*Assumptions!C9,0),(1+Assumptions!C14/Assumptions!C9)^(-13),"") -> 0.68095134 | H17: =IF(13<=ROUND(Assumptions!C8*Assumptions!C9,0),F17*G17,"") -> 17.023783 | I17: =IF(13<=ROUND(Assumptions!C8*Assumptions!C9,0),IF(13=1,H17,I16+H17),"") -> 265.87388
B18: =IF(14<=ROUND(Assumptions!C8*Assumptions!C9,0),14,"") -> 14 | C18: =IF(14<=ROUND(Assumptions!C8*Assumptions!C9,0),14/Assumptions!C9,"") -> 7 | D18: =IF(14<=ROUND(Assumptions!C8*Assumptions!C9,0),Assumptions!C6*Assumptions!C7/Assumptions!C9,"") -> 25 | E18: =IF(14=ROUND(Assumptions!C8*Assumptions!C9,0),Assumptions!C6,IF(14<ROUND(Assumptions!C8*Assumptions!C9,0),0,"")) -> 0 | F18: =IF(14<=ROUND(Assumptions!C8*Assumptions!C9,0),D18+E18,"") -> 25 | G18: =IF(14<=ROUND(Assumptions!C8*Assumptions!C9,0),(1+Assumptions!C14/Assumptions!C9)^(-14),"") -> 0.66111781 | H18: =IF(14<=ROUND(Assumptions!C8*Assumptions!C9,0),F18*G18,"") -> 16.527945 | I18: =IF(14<=ROUND(Assumptions!C8*Assumptions!C9,0),IF(14=1,H18,I17+H18),"") -> 282.40183
B19: =IF(15<=ROUND(Assumptions!C8*Assumptions!C9,0),15,"") -> 15 | C19: =IF(15<=ROUND(Assumptions!C8*Assumptions!C9,0),15/Assumptions!C9,"") -> 7.5 | D19: =IF(15<=ROUND(Assumptions!C8*Assumptions!C9,0),Assumptions!C6*Assumptions!C7/Assumptions!C9,"") -> 25 | E19: =IF(15=ROUND(Assumptions!C8*Assumptions!C9,0),Assumptions!C6,IF(15<ROUND(Assumptions!C8*Assumptions!C9,0),0,"")) -> 0 | F19: =IF(15<=ROUND(Assumptions!C8*Assumptions!C9,0),D19+E19,"") -> 25 | G19: =IF(15<=ROUND(Assumptions!C8*Assumptions!C9,0),(1+Assumptions!C14/Assumptions!C9)^(-15),"") -> 0.64186195 | H19: =IF(15<=ROUND(Assumptions!C8*Assumptions!C9,0),F19*G19,"") -> 16.046549 | I19: =IF(15<=ROUND(Assumptions!C8*Assumptions!C9,0),IF(15=1,H19,I18+H19),"") -> 298.44838
B20: =IF(16<=ROUND(Assumptions!C8*Assumptions!C9,0),16,"") -> 16 | C20: =IF(16<=ROUND(Assumptions!C8*Assumptions!C9,0),16/Assumptions!C9,"") -> 8 | D20: =IF(16<=ROUND(Assumptions!C8*Assumptions!C9,0),Assumptions!C6*Assumptions!C7/Assumptions!C9,"") -> 25 | E20: =IF(16=ROUND(Assumptions!C8*Assumptions!C9,0),Assumptions!C6,IF(16<ROUND(Assumptions!C8*Assumptions!C9,0),0,"")) -> 0 | F20: =IF(16<=ROUND(Assumptions!C8*Assumptions!C9,0),D20+E20,"") -> 25 | G20: =IF(16<=ROUND(Assumptions!C8*Assumptions!C9,0),(1+Assumptions!C14/Assumptions!C9)^(-16),"") -> 0.62316694 | H20: =IF(16<=ROUND(Assumptions!C8*Assumptions!C9,0),F20*G20,"") -> 15.579173 | I20: =IF(16<=ROUND(Assumptions!C8*Assumptions!C9,0),IF(16=1,H20,I19+H20),"") -> 314.02755
B21: =IF(17<=ROUND(Assumptions!C8*Assumptions!C9,0),17,"") -> 17 | C21: =IF(17<=ROUND(Assumptions!C8*Assumptions!C9,0),17/Assumptions!C9,"") -> 8.5 | D21: =IF(17<=ROUND(Assumptions!C8*Assumptions!C9,0),Assumptions!C6*Assumptions!C7/Assumptions!C9,"") -> 25 | E21: =IF(17=ROUND(Assumptions!C8*Assumptions!C9,0),Assumptions!C6,IF(17<ROUND(Assumptions!C8*Assumptions!C9,0),0,"")) -> 0 | F21: =IF(17<=ROUND(Assumptions!C8*Assumptions!C9,0),D21+E21,"") -> 25 | G21: =IF(17<=ROUND(Assumptions!C8*Assumptions!C9,0),(1+Assumptions!C14/Assumptions!C9)^(-17),"") -> 0.60501645 | H21: =IF(17<=ROUND(Assumptions!C8*Assumptions!C9,0),F21*G21,"") -> 15.125411 | I21: =IF(17<=ROUND(Assumptions!C8*Assumptions!C9,0),IF(17=1,H21,I20+H21),"") -> 329.15296
B22: =IF(18<=ROUND(Assumptions!C8*Assumptions!C9,0),18,"") -> 18 | C22: =IF(18<=ROUND(Assumptions!C8*Assumptions!C9,0),18/Assumptions!C9,"") -> 9 | D22: =IF(18<=ROUND(Assumptions!C8*Assumptions!C9,0),Assumptions!C6*Assumptions!C7/Assumptions!C9,"") -> 25 | E22: =IF(18=ROUND(Assumptions!C8*Assumptions!C9,0),Assumptions!C6,IF(18<ROUND(Assumptions!C8*Assumptions!C9,0),0,"")) -> 0 | F22: =IF(18<=ROUND(Assumptions!C8*Assumptions!C9,0),D22+E22,"") -> 25 | G22: =IF(18<=ROUND(Assumptions!C8*Assumptions!C9,0),(1+Assumptions!C14/Assumptions!C9)^(-18),"") -> 0.58739461 | H22: =IF(18<=ROUND(Assumptions!C8*Assumptions!C9,0),F22*G22,"") -> 14.684865 | I22: =IF(18<=ROUND(Assumptions!C8*Assumptions!C9,0),IF(18=1,H22,I21+H22),"") -> 343.83783
B23: =IF(19<=ROUND(Assumptions!C8*Assumptions!C9,0),19,"") -> 19 | C23: =IF(19<=ROUND(Assumptions!C8*Assumptions!C9,0),19/Assumptions!C9,"") -> 9.5 | D23: =IF(19<=ROUND(Assumptions!C8*Assumptions!C9,0),Assumptions!C6*Assumptions!C7/Assumptions!C9,"") -> 25 | E23: =IF(19=ROUND(Assumptions!C8*Assumptions!C9,0),Assumptions!C6,IF(19<ROUND(Assumptions!C8*Assumptions!C9,0),0,"")) -> 0 | F23: =IF(19<=ROUND(Assumptions!C8*Assumptions!C9,0),D23+E23,"") -> 25 | G23: =IF(19<=ROUND(Assumptions!C8*Assumptions!C9,0),(1+Assumptions!C14/Assumptions!C9)^(-19),"") -> 0.57028603 | H23: =IF(19<=ROUND(Assumptions!C8*Assumptions!C9,0),F23*G23,"") -> 14.257151 | I23: =IF(19<=ROUND(Assumptions!C8*Assumptions!C9,0),IF(19=1,H23,I22+H23),"") -> 358.09498
B24: =IF(20<=ROUND(Assumptions!C8*Assumptions!C9,0),20,"") -> 20 | C24: =IF(20<=ROUND(Assumptions!C8*Assumptions!C9,0),20/Assumptions!C9,"") -> 10 | D24: =IF(20<=ROUND(Assumptions!C8*Assumptions!C9,0),Assumptions!C6*Assumptions!C7/Assumptions!C9,"") -> 25 | E24: =IF(20=ROUND(Assumptions!C8*Assumptions!C9,0),Assumptions!C6,IF(20<ROUND(Assumptions!C8*Assumptions!C9,0),0,"")) -> 1000 | F24: =IF(20<=ROUND(Assumptions!C8*Assumptions!C9,0),D24+E24,"") -> 1025 | G24: =IF(20<=ROUND(Assumptions!C8*Assumptions!C9,0),(1+Assumptions!C14/Assumptions!C9)^(-20),"") -> 0.55367575 | H24: =IF(20<=ROUND(Assumptions!C8*Assumptions!C9,0),F24*G24,"") -> 567.51765 | I24: =IF(20<=ROUND(Assumptions!C8*Assumptions!C9,0),IF(20=1,H24,I23+H24),"") -> 925.61263
B25: =IF(21<=ROUND(Assumptions!C8*Assumptions!C9,0),21,"") | C25: =IF(21<=ROUND(Assumptions!C8*Assumptions!C9,0),21/Assumptions!C9,"") | D25: =IF(21<=ROUND(Assumptions!C8*Assumptions!C9,0),Assumptions!C6*Assumptions!C7/Assumptions!C9,"") | E25: =IF(21=ROUND(Assumptions!C8*Assumptions!C9,0),Assumptions!C6,IF(21<ROUND(Assumptions!C8*Assumptions!C9,0),0,"")) | F25: =IF(21<=ROUND(Assumptions!C8*Assumptions!C9,0),D25+E25,"") | G25: =IF(21<=ROUND(Assumptions!C8*Assumptions!C9,0),(1+Assumptions!C14/Assumptions!C9)^(-21),"") | H25: =IF(21<=ROUND(Assumptions!C8*Assumptions!C9,0),F25*G25,"") | I25: =IF(21<=ROUND(Assumptions!C8*Assumptions!C9,0),IF(21=1,H25,I24+H25),"")
B26: =IF(22<=ROUND(Assumptions!C8*Assumptions!C9,0),22,"") | C26: =IF(22<=ROUND(Assumptions!C8*Assumptions!C9,0),22/Assumptions!C9,"") | D26: =IF(22<=ROUND(Assumptions!C8*Assumptions!C9,0),Assumptions!C6*Assumptions!C7/Assumptions!C9,"") | E26: =IF(22=ROUND(Assumptions!C8*Assumptions!C9,0),Assumptions!C6,IF(22<ROUND(Assumptions!C8*Assumptions!C9,0),0,"")) | F26: =IF(22<=ROUND(Assumptions!C8*Assumptions!C9,0),D26+E26,"") | G26: =IF(22<=ROUND(Assumptions!C8*Assumptions!C9,0),(1+Assumptions!C14/Assumptions!C9)^(-22),"") | H26: =IF(22<=ROUND(Assumptions!C8*Assumptions!C9,0),F26*G26,"") | I26: =IF(22<=ROUND(Assumptions!C8*Assumptions!C9,0),IF(22=1,H26,I25+H26),"")
B27: =IF(23<=ROUND(Assumptions!C8*Assumptions!C9,0),23,"") | C27: =IF(23<=ROUND(Assumptions!C8*Assumptions!C9,0),23/Assumptions!C9,"") | D27: =IF(23<=ROUND(Assumptions!C8*Assumptions!C9,0),Assumptions!C6*Assumptions!C7/Assumptions!C9,"") | E27: =IF(23=ROUND(Assumptions!C8*Assumptions!C9,0),Assumptions!C6,IF(23<ROUND(Assumptions!C8*Assumptions!C9,0),0,"")) | F27: =IF(23<=ROUND(Assumptions!C8*Assumptions!C9,0),D27+E27,"") | G27: =IF(23<=ROUND(Assumptions!C8*Assumptions!C9,0),(1+Assumptions!C14/Assumptions!C9)^(-23),"") | H27: =IF(23<=ROUND(Assumptions!C8*Assumptions!C9,0),F27*G27,"") | I27: =IF(23<=ROUND(Assumptions!C8*Assumptions!C9,0),IF(23=1,H27,I26+H27),"")
B28: =IF(24<=ROUND(Assumptions!C8*Assumptions!C9,0),24,"") | C28: =IF(24<=ROUND(Assumptions!C8*Assumptions!C9,0),24/Assumptions!C9,"") | D28: =IF(24<=ROUND(Assumptions!C8*Assumptions!C9,0),Assumptions!C6*Assumptions!C7/Assumptions!C9,"") | E28: =IF(24=ROUND(Assumptions!C8*Assumptions!C9,0),Assumptions!C6,IF(24<ROUND(Assumptions!C8*Assumptions!C9,0),0,"")) | F28: =IF(24<=ROUND(Assumptions!C8*Assumptions!C9,0),D28+E28,"") | G28: =IF(24<=ROUND(Assumptions!C8*Assumptions!C9,0),(1+Assumptions!C14/Assumptions!C9)^(-24),"") | H28: =IF(24<=ROUND(Assumptions!C8*Assumptions!C9,0),F28*G28,"") | I28: =IF(24<=ROUND(Assumptions!C8*Assumptions!C9,0),IF(24=1,H28,I27+H28),"")
B29: =IF(25<=ROUND(Assumptions!C8*Assumptions!C9,0),25,"") | C29: =IF(25<=ROUND(Assumptions!C8*Assumptions!C9,0),25/Assumptions!C9,"") | D29: =IF(25<=ROUND(Assumptions!C8*Assumptions!C9,0),Assumptions!C6*Assumptions!C7/Assumptions!C9,"") | E29: =IF(25=ROUND(Assumptions!C8*Assumptions!C9,0),Assumptions!C6,IF(25<ROUND(Assumptions!C8*Assumptions!C9,0),0,"")) | F29: =IF(25<=ROUND(Assumptions!C8*Assumptions!C9,0),D29+E29,"") | G29: =IF(25<=ROUND(Assumptions!C8*Assumptions!C9,0),(1+Assumptions!C14/Assumptions!C9)^(-25),"") | H29: =IF(25<=ROUND(Assumptions!C8*Assumptions!C9,0),F29*G29,"") | I29: =IF(25<=ROUND(Assumptions!C8*Assumptions!C9,0),IF(25=1,H29,I28+H29),"")
B30: =IF(26<=ROUND(Assumptions!C8*Assumptions!C9,0),26,"") | C30: =IF(26<=ROUND(Assumptions!C8*Assumptions!C9,0),26/Assumptions!C9,"") | D30: =IF(26<=ROUND(Assumptions!C8*Assumptions!C9,0),Assumptions!C6*Assumptions!C7/Assumptions!C9,"") | E30: =IF(26=ROUND(Assumptions!C8*Assumptions!C9,0),Assumptions!C6,IF(26<ROUND(Assumptions!C8*Assumptions!C9,0),0,"")) | F30: =IF(26<=ROUND(Assumptions!C8*Assumptions!C9,0),D30+E30,"") | G30: =IF(26<=ROUND(Assumptions!C8*Assumptions!C9,0),(1+Assumptions!C14/Assumptions!C9)^(-26),"") | H30: =IF(26<=ROUND(Assumptions!C8*Assumptions!C9,0),F30*G30,"") | I30: =IF(26<=ROUND(Assumptions!C8*Assumptions!C9,0),IF(26=1,H30,I29+H30),"")
B31: =IF(27<=ROUND(Assumptions!C8*Assumptions!C9,0),27,"") | C31: =IF(27<=ROUND(Assumptions!C8*Assumptions!C9,0),27/Assumptions!C9,"") | D31: =IF(27<=ROUND(Assumptions!C8*Assumptions!C9,0),Assumptions!C6*Assumptions!C7/Assumptions!C9,"") | E31: =IF(27=ROUND(Assumptions!C8*Assumptions!C9,0),Assumptions!C6,IF(27<ROUND(Assumptions!C8*Assumptions!C9,0),0,"")) | F31: =IF(27<=ROUND(Assumptions!C8*Assumptions!C9,0),D31+E31,"") | G31: =IF(27<=ROUND(Assumptions!C8*Assumptions!C9,0),(1+Assumptions!C14/Assumptions!C9)^(-27),"") | H31: =IF(27<=ROUND(Assumptions!C8*Assumptions!C9,0),F31*G31,"") | I31: =IF(27<=ROUND(Assumptions!C8*Assumptions!C9,0),IF(27=1,H31,I30+H31),"")
B32: =IF(28<=ROUND(Assumptions!C8*Assumptions!C9,0),28,"") | C32: =IF(28<=ROUND(Assumptions!C8*Assumptions!C9,0),28/Assumptions!C9,"") | D32: =IF(28<=ROUND(Assumptions!C8*Assumptions!C9,0),Assumptions!C6*Assumptions!C7/Assumptions!C9,"") | E32: =IF(28=ROUND(Assumptions!C8*Assumptions!C9,0),Assumptions!C6,IF(28<ROUND(Assumptions!C8*Assumptions!C9,0),0,"")) | F32: =IF(28<=ROUND(Assumptions!C8*Assumptions!C9,0),D32+E32,"") | G32: =IF(28<=ROUND(Assumptions!C8*Assumptions!C9,0),(1+Assumptions!C14/Assumptions!C9)^(-28),"") | H32: =IF(28<=ROUND(Assumptions!C8*Assumptions!C9,0),F32*G32,"") | I32: =IF(28<=ROUND(Assumptions!C8*Assumptions!C9,0),IF(28=1,H32,I31+H32),"")
B33: =IF(29<=ROUND(Assumptions!C8*Assumptions!C9,0),29,"") | C33: =IF(29<=ROUND(Assumptions!C8*Assumptions!C9,0),29/Assumptions!C9,"") | D33: =IF(29<=ROUND(Assumptions!C8*Assumptions!C9,0),Assumptions!C6*Assumptions!C7/Assumptions!C9,"") | E33: =IF(29=ROUND(Assumptions!C8*Assumptions!C9,0),Assumptions!C6,IF(29<ROUND(Assumptions!C8*Assumptions!C9,0),0,"")) | F33: =IF(29<=ROUND(Assumptions!C8*Assumptions!C9,0),D33+E33,"") | G33: =IF(29<=ROUND(Assumptions!C8*Assumptions!C9,0),(1+Assumptions!C14/Assumptions!C9)^(-29),"") | H33: =IF(29<=ROUND(Assumptions!C8*Assumptions!C9,0),F33*G33,"") | I33: =IF(29<=ROUND(Assumptions!C8*Assumptions!C9,0),IF(29=1,H33,I32+H33),"")
B34: =IF(30<=ROUND(Assumptions!C8*Assumptions!C9,0),30,"") | C34: =IF(30<=ROUND(Assumptions!C8*Assumptions!C9,0),30/Assumptions!C9,"") | D34: =IF(30<=ROUND(Assumptions!C8*Assumptions!C9,0),Assumptions!C6*Assumptions!C7/Assumptions!C9,"") | E34: =IF(30=ROUND(Assumptions!C8*Assumptions!C9,0),Assumptions!C6,IF(30<ROUND(Assumptions!C8*Assumptions!C9,0),0,"")) | F34: =IF(30<=ROUND(Assumptions!C8*Assumptions!C9,0),D34+E34,"") | G34: =IF(30<=ROUND(Assumptions!C8*Assumptions!C9,0),(1+Assumptions!C14/Assumptions!C9)^(-30),"") | H34: =IF(30<=ROUND(Assumptions!C8*Assumptions!C9,0),F34*G34,"") | I34: =IF(30<=ROUND(Assumptions!C8*Assumptions!C9,0),IF(30=1,H34,I33+H34),"")
B35: =IF(31<=ROUND(Assumptions!C8*Assumptions!C9,0),31,"") | C35: =IF(31<=ROUND(Assumptions!C8*Assumptions!C9,0),31/Assumptions!C9,"") | D35: =IF(31<=ROUND(Assumptions!C8*Assumptions!C9,0),Assumptions!C6*Assumptions!C7/Assumptions!C9,"") | E35: =IF(31=ROUND(Assumptions!C8*Assumptions!C9,0),Assumptions!C6,IF(31<ROUND(Assumptions!C8*Assumptions!C9,0),0,"")) | F35: =IF(31<=ROUND(Assumptions!C8*Assumptions!C9,0),D35+E35,"") | G35: =IF(31<=ROUND(Assumptions!C8*Assumptions!C9,0),(1+Assumptions!C14/Assumptions!C9)^(-31),"") | H35: =IF(31<=ROUND(Assumptions!C8*Assumptions!C9,0),F35*G35,"") | I35: =IF(31<=ROUND(Assumptions!C8*Assumptions!C9,0),IF(31=1,H35,I34+H35),"")
B36: =IF(32<=ROUND(Assumptions!C8*Assumptions!C9,0),32,"") | C36: =IF(32<=ROUND(Assumptions!C8*Assumptions!C9,0),32/Assumptions!C9,"") | D36: =IF(32<=ROUND(Assumptions!C8*Assumptions!C9,0),Assumptions!C6*Assumptions!C7/Assumptions!C9,"") | E36: =IF(32=ROUND(Assumptions!C8*Assumptions!C9,0),Assumptions!C6,IF(32<ROUND(Assumptions!C8*Assumptions!C9,0),0,"")) | F36: =IF(32<=ROUND(Assumptions!C8*Assumptions!C9,0),D36+E36,"") | G36: =IF(32<=ROUND(Assumptions!C8*Assumptions!C9,0),(1+Assumptions!C14/Assumptions!C9)^(-32),"") | H36: =IF(32<=ROUND(Assumptions!C8*Assumptions!C9,0),F36*G36,"") | I36: =IF(32<=ROUND(Assumptions!C8*Assumptions!C9,0),IF(32=1,H36,I35+H36),"")
B37: =IF(33<=ROUND(Assumptions!C8*Assumptions!C9,0),33,"") | C37: =IF(33<=ROUND(Assumptions!C8*Assumptions!C9,0),33/Assumptions!C9,"") | D37: =IF(33<=ROUND(Assumptions!C8*Assumptions!C9,0),Assumptions!C6*Assumptions!C7/Assumptions!C9,"") | E37: =IF(33=ROUND(Assumptions!C8*Assumptions!C9,0),Assumptions!C6,IF(33<ROUND(Assumptions!C8*Assumptions!C9,0),0,"")) | F37: =IF(33<=ROUND(Assumptions!C8*Assumptions!C9,0),D37+E37,"") | G37: =IF(33<=ROUND(Assumptions!C8*Assumptions!C9,0),(1+Assumptions!C14/Assumptions!C9)^(-33),"") | H37: =IF(33<=ROUND(Assumptions!C8*Assumptions!C9,0),F37*G37,"") | I37: =IF(33<=ROUND(Assumptions!C8*Assumptions!C9,0),IF(33=1,H37,I36+H37),"")
B38: =IF(34<=ROUND(Assumptions!C8*Assumptions!C9,0),34,"") | C38: =IF(34<=ROUND(Assumptions!C8*Assumptions!C9,0),34/Assumptions!C9,"") | D38: =IF(34<=ROUND(Assumptions!C8*Assumptions!C9,0),Assumptions!C6*Assumptions!C7/Assumptions!C9,"") | E38: =IF(34=ROUND(Assumptions!C8*Assumptions!C9,0),Assumptions!C6,IF(34<ROUND(Assumptions!C8*Assumptions!C9,0),0,"")) | F38: =IF(34<=ROUND(Assumptions!C8*Assumptions!C9,0),D38+E38,"") | G38: =IF(34<=ROUND(Assumptions!C8*Assumptions!C9,0),(1+Assumptions!C14/Assumptions!C9)^(-34),"") | H38: =IF(34<=ROUND(Assumptions!C8*Assumptions!C9,0),F38*G38,"") | I38: =IF(34<=ROUND(Assumptions!C8*Assumptions!C9,0),IF(34=1,H38,I37+H38),"")
B39: =IF(35<=ROUND(Assumptions!C8*Assumptions!C9,0),35,"") | C39: =IF(35<=ROUND(Assumptions!C8*Assumptions!C9,0),35/Assumptions!C9,"") | D39: =IF(35<=ROUND(Assumptions!C8*Assumptions!C9,0),Assumptions!C6*Assumptions!C7/Assumptions!C9,"") | E39: =IF(35=ROUND(Assumptions!C8*Assumptions!C9,0),Assumptions!C6,IF(35<ROUND(Assumptions!C8*Assumptions!C9,0),0,"")) | F39: =IF(35<=ROUND(Assumptions!C8*Assumptions!C9,0),D39+E39,"") | G39: =IF(35<=ROUND(Assumptions!C8*Assumptions!C9,0),(1+Assumptions!C14/Assumptions!C9)^(-35),"") | H39: =IF(35<=ROUND(Assumptions!C8*Assumptions!C9,0),F39*G39,"") | I39: =IF(35<=ROUND(Assumptions!C8*Assumptions!C9,0),IF(35=1,H39,I38+H39),"")
B40: =IF(36<=ROUND(Assumptions!C8*Assumptions!C9,0),36,"") | C40: =IF(36<=ROUND(Assumptions!C8*Assumptions!C9,0),36/Assumptions!C9,"") | D40: =IF(36<=ROUND(Assumptions!C8*Assumptions!C9,0),Assumptions!C6*Assumptions!C7/Assumptions!C9,"") | E40: =IF(36=ROUND(Assumptions!C8*Assumptions!C9,0),Assumptions!C6,IF(36<ROUND(Assumptions!C8*Assumptions!C9,0),0,"")) | F40: =IF(36<=ROUND(Assumptions!C8*Assumptions!C9,0),D40+E40,"") | G40: =IF(36<=ROUND(Assumptions!C8*Assumptions!C9,0),(1+Assumptions!C14/Assumptions!C9)^(-36),"") | H40: =IF(36<=ROUND(Assumptions!C8*Assumptions!C9,0),F40*G40,"") | I40: =IF(36<=ROUND(Assumptions!C8*Assumptions!C9,0),IF(36=1,H40,I39+H40),"")
B41: =IF(37<=ROUND(Assumptions!C8*Assumptions!C9,0),37,"") | C41: =IF(37<=ROUND(Assumptions!C8*Assumptions!C9,0),37/Assumptions!C9,"") | D41: =IF(37<=ROUND(Assumptions!C8*Assumptions!C9,0),Assumptions!C6*Assumptions!C7/Assumptions!C9,"") | E41: =IF(37=ROUND(Assumptions!C8*Assumptions!C9,0),Assumptions!C6,IF(37<ROUND(Assumptions!C8*Assumptions!C9,0),0,"")) | F41: =IF(37<=ROUND(Assumptions!C8*Assumptions!C9,0),D41+E41,"") | G41: =IF(37<=ROUND(Assumptions!C8*Assumptions!C9,0),(1+Assumptions!C14/Assumptions!C9)^(-37),"") | H41: =IF(37<=ROUND(Assumptions!C8*Assumptions!C9,0),F41*G41,"") | I41: =IF(37<=ROUND(Assumptions!C8*Assumptions!C9,0),IF(37=1,H41,I40+H41),"")
...

Sheet Risk Metrics
A1: Yariverse Bank | Fixed Income Analytics | Risk Metrics
A2: RISK METRICS : Macaulay Duration · Modified Duration · DV01 · Convexity
B4: LINKED PRICES & RATES
B5: Clean Price ($) | C5: =Pricing!C19 -> 925.61263
B6: Annual YTM | C6: =Assumptions!C14 -> 0.06
B7: Periodic Yield (r) | C7: =Assumptions!C14/Assumptions!C9 -> 0.03
B8: Coupon Freq. | C8: =Assumptions!C9 -> 2
B9: Periods (N) | C9: =ROUND(Assumptions!C8*Assumptions!C9,0) -> 20
B11: MACAULAY DURATION [Σ t×PV(CF_t) / P]
B12: Macaulay Duration (years) | C12: =SUMPRODUCT(IFERROR('Cash Flows'!C5:C44*'Cash Flows'!H5:H44,0))/Pricing!C19 -> 0.085285055
B14: MODIFIED DURATION [MacD / (1+r)]
B15: Modified Duration | C15: =C12/(1+Assumptions!C14/Assumptions!C9) -> 0.082801024 | D15: Macaulay Duration / (1 + r)
B17: DV01 [ModDur × Price × 0.0001]
B18: DV01 — Dollar Value of 1 Basis Point ($) | C18: =C15*Pricing!C19*0.0001 -> 0.0076641673 | D18: ≈ Mod. Duration × Price × 0.0001
B20: CONVEXITY [Σ t(t+1)×PV(CF_t) / (P×(1+r)²×Freq²)]
B21: Convexity (annual) | C21: =SUMPRODUCT(N('Cash Flows'!B5:B44)*(N('Cash Flows'!B5:B44)+1)*N('Cash Flows'!H5:H44))/(Pricing!C19*(1+Assumptions!C14/Assumptions!C9)^2*Assumptions!C9^2) -> 0.012358594
B23: PRICE SENSITIVITY — Duration & Convexity Approximation
B24: Yield Shock Input (basis points) | C24: 100
B25: Duration-Only Price Estimate ($) | C25: =Pricing!C19*(1-C15*C24/10000) -> 924.84621 | D25: P×(1−ModDur×Δy)
B26: Duration + Convexity Estimate ($) | C26: =Pricing!C19*(1-C15*C24/10000+0.5*C21*(C24/10000)^2) -> 924.84678 | D26: P×(1−ModDur×Δy+½Conv×Δy²)
B27: True Repriced Bond ($) | C27: =Assumptions!C6*Assumptions!C7/Assumptions!C9*(1-(1+(Assumptions!C14+C24/10000)/Assumptions!C9)^(-ROUND(Assumptions!C8*Assumptions!C9,0)))/((Assumptions!C14+C24/10000)/Assumptions!C9)+Assumptions!C6*(1+(Assumptions!C14+C24/10000)/Assumptions!C9)^(-ROUND(Assumptions!C8*Assumptions!C9,0)) -> 857.87597 | D27: Full DCF at shocked yield
B28: Convexity Benefit ($) | C28: =C27-C26 -> -66.970814 | D28: True Price − Duration-Only estimate

Sheet Price-Yield
A1: Yariverse Bank | Fixed Income Analytics | Price–Yield Table
A2: PRICE-YIELD TABLE : 29 scenarios ±7% around market yield
B4: Yield (%) | C4: Clean Price ($) | D4: Price / Par | E4: Δ Price ($) | F4: Status | G4: Dur-Only Est ($)
B5: =Assumptions!C14-0.07 -> -0.01 | C5: =IFERROR(Assumptions!C6*Assumptions!C7/Assumptions!C9*(1-(1+((Assumptions!C14-0.07)/Assumptions!C9))^(-ROUND(Assumptions!C8*Assumptions!C9,0)))/(((Assumptions!C14-0.07)/Assumptions!C9))+Assumptions!C6*(1+((Assumptions!C14-0.07)/Assumptions!C9))^(-ROUND(Assumptions!C8*Assumptions!C9,0)),ROUND(Assumptions!C8*Assumptions!C9,0)*Assumptions!C6*Assumptions!C7/Assumptions!C9+Assumptions!C6) -> 1632.689 | D5: =C5/Assumptions!C6 -> 1.632689 | E5: =C5-Pricing!C19 -> 707.07639 | F5: =IF(B5>Assumptions!C7,"DISCOUNT",IF(B5<Assumptions!C7,"PREMIUM","PAR")) -> PREMIUM | G5: =Pricing!C19*(1-'Risk Metrics'!C15*(-0.07)) -> 930.97754
B6: =Assumptions!C14-0.065 -> -0.005 | C6: =IFERROR(Assumptions!C6*Assumptions!C7/Assumptions!C9*(1-(1+((Assumptions!C14-0.065)/Assumptions!C9))^(-ROUND(Assumptions!C8*Assumptions!C9,0)))/(((Assumptions!C14-0.065)/Assumptions!C9))+Assumptions!C6*(1+((Assumptions!C14-0.065)/Assumptions!C9))^(-ROUND(Assumptions!C8*Assumptions!C9,0)),ROUND(Assumptions!C8*Assumptions!C9,0)*Assumptions!C6*Assumptions!C7/Assumptions!C9+Assumptions!C6) -> 1564.706 | D6: =C6/Assumptions!C6 -> 1.564706 | E6: =C6-Pricing!C19 -> 639.09341 | F6: =IF(B6>Assumptions!C7,"DISCOUNT",IF(B6<Assumptions!C7,"PREMIUM","PAR")) -> PREMIUM | G6: =Pricing!C19*(1-'Risk Metrics'!C15*(-0.065)) -> 930.59433
B7: =Assumptions!C14-0.06 -> 0 | C7: =IFERROR(Assumptions!C6*Assumptions!C7/Assumptions!C9*(1-(1+((Assumptions!C14-0.06)/Assumptions!C9))^(-ROUND(Assumptions!C8*Assumptions!C9,0)))/(((Assumptions!C14-0.06)/Assumptions!C9))+Assumptions!C6*(1+((Assumptions!C14-0.06)/Assumptions!C9))^(-ROUND(Assumptions!C8*Assumptions!C9,0)),ROUND(Assumptions!C8*Assumptions!C9,0)*Assumptions!C6*Assumptions!C7/Assumptions!C9+Assumptions!C6) -> 1500 | D7: =C7/Assumptions!C6 -> 1.5 | E7: =C7-Pricing!C19 -> 574.38737 | F7: =IF(B7>Assumptions!C7,"DISCOUNT",IF(B7<Assumptions!C7,"PREMIUM","PAR")) -> PREMIUM | G7: =Pricing!C19*(1-'Risk Metrics'!C15*(-0.06)) -> 930.21113
B8: =Assumptions!C14-0.055 -> 0.005 | C8: =IFERROR(Assumptions!C6*Assumptions!C7/Assumptions!C9*(1-(1+((Assumptions!C14-0.055)/Assumptions!C9))^(-ROUND(Assumptions!C8*Assumptions!C9,0)))/(((Assumptions!C14-0.055)/Assumptions!C9))+Assumptions!C6*(1+((Assumptions!C14-0.055)/Assumptions!C9))^(-ROUND(Assumptions!C8*Assumptions!C9,0)),ROUND(Assumptions!C8*Assumptions!C9,0)*Assumptions!C6*Assumptions!C7/Assumptions!C9+Assumptions!C6) -> 1438.401 | D8: =C8/Assumptions!C6 -> 1.438401 | E8: =C8-Pricing!C19 -> 512.78836 | F8: =IF(B8>Assumptions!C7,"DISCOUNT",IF(B8<Assumptions!C7,"PREMIUM","PAR")) -> PREMIUM | G8: =Pricing!C19*(1-'Risk Metrics'!C15*(-0.055)) -> 929.82792
B9: =Assumptions!C14-0.05 -> 0.01 | C9: =IFERROR(Assumptions!C6*Assumptions!C7/Assumptions!C9*(1-(1+((Assumptions!C14-0.05)/Assumptions!C9))^(-ROUND(Assumptions!C8*Assumptions!C9,0)))/(((Assumptions!C14-0.05)/Assumptions!C9))+Assumptions!C6*(1+((Assumptions!C14-0.05)/Assumptions!C9))^(-ROUND(Assumptions!C8*Assumptions!C9,0)),ROUND(Assumptions!C8*Assumptions!C9,0)*Assumptions!C6*Assumptions!C7/Assumptions!C9+Assumptions!C6) -> 1379.7484 | D9: =C9/Assumptions!C6 -> 1.3797484 | E9: =C9-Pricing!C19 -> 454.13576 | F9: =IF(B9>Assumptions!C7,"DISCOUNT",IF(B9<Assumptions!C7,"PREMIUM","PAR")) -> PREMIUM | G9: =Pricing!C19*(1-'Risk Metrics'!C15*(-0.05)) -> 929.44471
B10: =Assumptions!C14-0.045 -> 0.015 | C10: =IFERROR(Assumptions!C6*Assumptions!C7/Assumptions!C9*(1-(1+((Assumptions!C14-0.045)/Assumptions!C9))^(-ROUND(Assumptions!C8*Assumptions!C9,0)))/(((Assumptions!C14-0.045)/Assumptions!C9))+Assumptions!C6*(1+((Assumptions!C14-0.045)/Assumptions!C9))^(-ROUND(Assumptions!C8*Assumptions!C9,0)),ROUND(Assumptions!C8*Assumptions!C9,0)*Assumptions!C6*Assumptions!C7/Assumptions!C9+Assumptions!C6) -> 1323.8903 | D10: =C10/Assumptions!C6 -> 1.3238903 | E10: =C10-Pricing!C19 -> 398.27772 | F10: =IF(B10>Assumptions!C7,"DISCOUNT",IF(B10<Assumptions!C7,"PREMIUM","PAR")) -> PREMIUM | G10: =Pricing!C19*(1-'Risk Metrics'!C15*(-0.045)) -> 929.0615
B11: =Assumptions!C14-0.04 -> 0.02 | C11: =IFERROR(Assumptions!C6*Assumptions!C7/Assumptions!C9*(1-(1+((Assumptions!C14-0.04)/Assumptions!C9))^(-ROUND(Assumptions!C8*Assumptions!C9,0)))/(((Assumptions!C14-0.04)/Assumptions!C9))+Assumptions!C6*(1+((Assumptions!C14-0.04)/Assumptions!C9))^(-ROUND(Assumptions!C8*Assumptions!C9,0)),ROUND(Assumptions!C8*Assumptions!C9,0)*Assumptions!C6*Assumptions!C7/Assumptions!C9+Assumptions!C6) -> 1270.6833 | D11: =C11/Assumptions!C6 -> 1.2706833 | E11: =C11-Pricing!C19 -> 345.07067 | F11: =IF(B11>Assumptions!C7,"DISCOUNT",IF(B11<Assumptions!C7,"PREMIUM","PAR")) -> PREMIUM | G11: =Pricing!C19*(1-'Risk Metrics'!C15*(-0.04)) -> 928.67829
B12: =Assumptions!C14-0.035 -> 0.025 | C12: =IFERROR(Assumptions!C6*Assumptions!C7/Assumptions!C9*(1-(1+((Assumptions!C14-0.035)/Assumptions!C9))^(-ROUND(Assumptions!C8*Assumptions!C9,0)))/(((Assumptions!C14-0.035)/Assumptions!C9))+Assumptions!C6*(1+((Assumptions!C14-0.035)/Assumptions!C9))^(-ROUND(Assumptions!C8*Assumptions!C9,0)),ROUND(Assumptions!C8*Assumptions!C9,0)*Assumptions!C6*Assumptions!C7/Assumptions!C9+Assumptions!C6) -> 1219.9915 | D12: =C12/Assumptions!C6 -> 1.2199915 | E12: =C12-Pricing!C19 -> 294.37883 | F12: =IF(B12>Assumptions!C7,"DISCOUNT",IF(B12<Assumptions!C7,"PREMIUM","PAR")) -> PREMIUM | G12: =Pricing!C19*(1-'Risk Metrics'!C15*(-0.035)) -> 928.29508
B13: =Assumptions!C14-0.03 -> 0.03 | C13: =IFERROR(Assumptions!C6*Assumptions!C7/Assumptions!C9*(1-(1+((Assumptions!C14-0.03)/Assumptions!C9))^(-ROUND(Assumptions!C8*Assumptions!C9,0)))/(((Assumptions!C14-0.03)/Assumptions!C9))+Assumptions!C6*(1+((Assumptions!C14-0.03)/Assumptions!C9))^(-ROUND(Assumptions!C8*Assumptions!C9,0)),ROUND(Assumptions!C8*Assumptions!C9,0)*Assumptions!C6*Assumptions!C7/Assumptions!C9+Assumptions!C6) -> 1171.6864 | D13: =C13/Assumptions!C6 -> 1.1716864 | E13: =C13-Pricing!C19 -> 246.07376 | F13: =IF(B13>Assumptions!C7,"DISCOUNT",IF(B13<Assumptions!C7,"PREMIUM","PAR")) -> PREMIUM | G13: =Pricing!C19*(1-'Risk Metrics'!C15*(-0.03)) -> 927.91188
B14: =Assumptions!C14-0.025 -> 0.035 | C14: =IFERROR(Assumptions!C6*Assumptions!C7/Assumptions!C9*(1-(1+((Assumptions!C14-0.025)/Assumptions!C9))^(-ROUND(Assumptions!C8*Assumptions!C9,0)))/(((Assumptions!C14-0.025)/Assumptions!C9))+Assumptions!C6*(1+((Assumptions!C14-0.025)/Assumptions!C9))^(-ROUND(Assumptions!C8*Assumptions!C9,0)),ROUND(Assumptions!C8*Assumptions!C9,0)*Assumptions!C6*Assumptions!C7/Assumptions!C9+Assumptions!C6) -> 1125.6466 | D14: =C14/Assumptions!C6 -> 1.1256466 | E14: =C14-Pricing!C19 -> 200.03398 | F14: =IF(B14>Assumptions!C7,"DISCOUNT",IF(B14<Assumptions!C7,"PREMIUM","PAR")) -> PREMIUM | G14: =Pricing!C19*(1-'Risk Metrics'!C15*(-0.025)) -> 927.52867
B15: =Assumptions!C14-0.02 -> 0.04 | C15: =IFERROR(Assumptions!C6*Assumptions!C7/Assumptions!C9*(1-(1+((Assumptions!C14-0.02)/Assumptions!C9))^(-ROUND(Assumptions!C8*Assumptions!C9,0)))/(((Assumptions!C14-0.02)/Assumptions!C9))+Assumptions!C6*(1+((Assumptions!C14-0.02)/Assumptions!C9))^(-ROUND(Assumptions!C8*Assumptions!C9,0)),ROUND(Assumptions!C8*Assumptions!C9,0)*Assumptions!C6*Assumptions!C7/Assumptions!C9+Assumptions!C6) -> 1081.7572 | D15: =C15/Assumptions!C6 -> 1.0817572 | E15: =C15-Pricing!C19 -> 156.14454 | F15: =IF(B15>Assumptions!C7,"DISCOUNT",IF(B15<Assumptions!C7,"PREMIUM","PAR")) -> PREMIUM | G15: =Pricing!C19*(1-'Risk Metrics'!C15*(-0.02)) -> 927.14546
B16: =Assumptions!C14-0.015 -> 0.045 | C16: =IFERROR(Assumptions!C6*Assumptions!C7/Assumptions!C9*(1-(1+((Assumptions!C14-0.015)/Assumptions!C9))^(-ROUND(Assumptions!C8*Assumptions!C9,0)))/(((Assumptions!C14-0.015)/Assumptions!C9))+Assumptions!C6*(1+((Assumptions!C14-0.015)/Assumptions!C9))^(-ROUND(Assumptions!C8*Assumptions!C9,0)),ROUND(Assumptions!C8*Assumptions!C9,0)*Assumptions!C6*Assumptions!C7/Assumptions!C9+Assumptions!C6) -> 1039.9093 | D16: =C16/Assumptions!C6 -> 1.0399093 | E16: =C16-Pricing!C19 -> 114.29666 | F16: =IF(B16>Assumptions!C7,"DISCOUNT",IF(B16<Assumptions!C7,"PREMIUM","PAR")) -> PREMIUM | G16: =Pricing!C19*(1-'Risk Metrics'!C15*(-0.015)) -> 926.76225
B17: =Assumptions!C14-0.01 -> 0.05 | C17: =IFERROR(Assumptions!C6*Assumptions!C7/Assumptions!C9*(1-(1+((Assumptions!C14-0.01)/Assumptions!C9))^(-ROUND(Assumptions!C8*Assumptions!C9,0)))/(((Assumptions!C14-0.01)/Assumptions!C9))+Assumptions!C6*(1+((Assumptions!C14-0.01)/Assumptions!C9))^(-ROUND(Assumptions!C8*Assumptions!C9,0)),ROUND(Assumptions!C8*Assumptions!C9,0)*Assumptions!C6*Assumptions!C7/Assumptions!C9+Assumptions!C6) -> 1000 | D17: =C17/Assumptions!C6 -> 1 | E17: =C17-Pricing!C19 -> 74.387374 | F17: =IF(B17>Assumptions!C7,"DISCOUNT",IF(B17<Assumptions!C7,"PREMIUM","PAR")) -> PAR | G17: =Pricing!C19*(1-'Risk Metrics'!C15*(-0.01)) -> 926.37904
B18: =Assumptions!C14-0.005 -> 0.055 | C18: =IFERROR(Assumptions!C6*Assumptions!C7/Assumptions!C9*(1-(1+((Assumptions!C14-0.005)/Assumptions!C9))^(-ROUND(Assumptions!C8*Assumptions!C9,0)))/(((Assumptions!C14-0.005)/Assumptions!C9))+Assumptions!C6*(1+((Assumptions!C14-0.005)/Assumptions!C9))^(-ROUND(Assumptions!C8*Assumptions!C9,0)),ROUND(Assumptions!C8*Assumptions!C9,0)*Assumptions!C6*Assumptions!C7/Assumptions!C9+Assumptions!C6) -> 961.93187 | D18: =C18/Assumptions!C6 -> 0.96193187 | E18: =C18-Pricing!C19 -> 36.319244 | F18: =IF(B18>Assumptions!C7,"DISCOUNT",IF(B18<Assumptions!C7,"PREMIUM","PAR")) -> DISCOUNT | G18: =Pricing!C19*(1-'Risk Metrics'!C15*(-0.005)) -> 925.99583
B19: =Assumptions!C14 -> 0.06 | C19: =IFERROR(Assumptions!C6*Assumptions!C7/Assumptions!C9*(1-(1+((Assumptions!C14+0)/Assumptions!C9))^(-ROUND(Assumptions!C8*Assumptions!C9,0)))/(((Assumptions!C14+0)/Assumptions!C9))+Assumptions!C6*(1+((Assumptions!C14+0)/Assumptions!C9))^(-ROUND(Assumptions!C8*Assumptions!C9,0)),ROUND(Assumptions!C8*Assumptions!C9,0)*Assumptions!C6*Assumptions!C7/Assumptions!C9+Assumptions!C6) -> 925.61263 | D19: =C19/Assumptions!C6 -> 0.92561263 | E19: =C19-Pricing!C19 -> 0 | F19: =IF(B19>Assumptions!C7,"DISCOUNT",IF(B19<Assumptions!C7,"PREMIUM","PAR")) -> DISCOUNT | G19: =Pricing!C19*(1-'Risk Metrics'!C15*(0)) -> 925.61263
B20: =+Assumptions!C14+0.005 -> 0.065 | C20: =IFERROR(Assumptions!C6*Assumptions!C7/Assumptions!C9*(1-(1+((Assumptions!C14+0.005)/Assumptions!C9))^(-ROUND(Assumptions!C8*Assumptions!C9,0)))/(((Assumptions!C14+0.005)/Assumptions!C9))+Assumptions!C6*(1+((Assumptions!C14+0.005)/Assumptions!C9))^(-ROUND(Assumptions!C8*Assumptions!C9,0)),ROUND(Assumptions!C8*Assumptions!C9,0)*Assumptions!C6*Assumptions!C7/Assumptions!C9+Assumptions!C6) -> 890.9549 | D20: =C20/Assumptions!C6 -> 0.8909549 | E20: =C20-Pricing!C19 -> -34.657722 | F20: =IF(B20>Assumptions!C7,"DISCOUNT",IF(B20<Assumptions!C7,"PREMIUM","PAR")) -> DISCOUNT | G20: =Pricing!C19*(1-'Risk Metrics'!C15*(0.005)) -> 925.22942
B21: =+Assumptions!C14+0.01 -> 0.07 | C21: =IFERROR(Assumptions!C6*Assumptions!C7/Assumptions!C9*(1-(1+((Assumptions!C14+0.01)/Assumptions!C9))^(-ROUND(Assumptions!C8*Assumptions!C9,0)))/(((Assumptions!C14+0.01)/Assumptions!C9))+Assumptions!C6*(1+((Assumptions!C14+0.01)/Assumptions!C9))^(-ROUND(Assumptions!C8*Assumptions!C9,0)),ROUND(Assumptions!C8*Assumptions!C9,0)*Assumptions!C6*Assumptions!C7/Assumptions!C9+Assumptions!C6) -> 857.87597 | D21: =C21/Assumptions!C6 -> 0.85787597 | E21: =C21-Pricing!C19 -> -67.736659 | F21: =IF(B21>Assumptions!C7,"DISCOUNT",IF(B21<Assumptions!C7,"PREMIUM","PAR")) -> DISCOUNT | G21: =Pricing!C19*(1-'Risk Metrics'!C15*(0.01)) -> 924.84621
B22: =+Assumptions!C14+0.015 -> 0.075 | C22: =IFERROR(Assumptions!C6*Assumptions!C7/Assumptions!C9*(1-(1+((Assumptions!C14+0.015)/Assumptions!C9))^(-ROUND(Assumptions!C8*Assumptions!C9,0)))/(((Assumptions!C14+0.015)/Assumptions!C9))+Assumptions!C6*(1+((Assumptions!C14+0.015)/Assumptions!C9))^(-ROUND(Assumptions!C8*Assumptions!C9,0)),ROUND(Assumptions!C8*Assumptions!C9,0)*Assumptions!C6*Assumptions!C7/Assumptions!C9+Assumptions!C6) -> 826.29745 | D22: =C22/Assumptions!C6 -> 0.82629745 | E22: =C22-Pricing!C19 -> -99.315178 | F22: =IF(B22>Assumptions!C7,"DISCOUNT",IF(B22<Assumptions!C7,"PREMIUM","PAR")) -> DISCOUNT | G22: =Pricing!C19*(1-'Risk Metrics'!C15*(0.015)) -> 924.463
B23: =+Assumptions!C14+0.02 -> 0.08 | C23: =IFERROR(Assumptions!C6*Assumptions!C7/Assumptions!C9*(1-(1+((Assumptions!C14+0.02)/Assumptions!C9))^(-ROUND(Assumptions!C8*Assumptions!C9,0)))/(((Assumptions!C14+0.02)/Assumptions!C9))+Assumptions!C6*(1+((Assumptions!C14+0.02)/Assumptions!C9))^(-ROUND(Assumptions!C8*Assumptions!C9,0)),ROUND(Assumptions!C8*Assumptions!C9,0)*Assumptions!C6*Assumptions!C7/Assumptions!C9+Assumptions!C6) -> 796.1451 | D23: =C23/Assumptions!C6 -> 0.7961451 | E23: =C23-Pricing!C19 -> -129.46752 | F23: =IF(B23>Assumptions!C7,"DISCOUNT",IF(B23<Assumptions!C7,"PREMIUM","PAR")) -> DISCOUNT | G23: =Pricing!C19*(1-'Risk Metrics'!C15*(0.02)) -> 924.07979
B24: =+Assumptions!C14+0.025 -> 0.085 | C24: =IFERROR(Assumptions!C6*Assumptions!C7/Assumptions!C9*(1-(1+((Assumptions!C14+0.025)/Assumptions!C9))^(-ROUND(Assumptions!C8*Assumptions!C9,0)))/(((Assumptions!C14+0.025)/Assumptions!C9))+Assumptions!C6*(1+((Assumptions!C14+0.025)/Assumptions!C9))^(-ROUND(Assumptions!C8*Assumptions!C9,0)),ROUND(Assumptions!C8*Assumptions!C9,0)*Assumptions!C6*Assumptions!C7/Assumptions!C9+Assumptions!C6) -> 767.3486 | D24: =C24/Assumptions!C6 -> 0.7673486 | E24: =C24-Pricing!C19 -> -158.26403 | F24: =IF(B24>Assumptions!C7,"DISCOUNT",IF(B24<Assumptions!C7,"PREMIUM","PAR")) -> DISCOUNT | G24: =Pricing!C19*(1-'Risk Metrics'!C15*(0.025)) -> 923.69658
B25: =+Assumptions!C14+0.03 -> 0.09 | C25: =IFERROR(Assumptions!C6*Assumptions!C7/Assumptions!C9*(1-(1+((Assumptions!C14+0.03)/Assumptions!C9))^(-ROUND(Assumptions!C8*Assumptions!C9,0)))/(((Assumptions!C14+0.03)/Assumptions!C9))+Assumptions!C6*(1+((Assumptions!C14+0.03)/Assumptions!C9))^(-ROUND(Assumptions!C8*Assumptions!C9,0)),ROUND(Assumptions!C8*Assumptions!C9,0)*Assumptions!C6*Assumptions!C7/Assumptions!C9+Assumptions!C6) -> 739.84127 | D25: =C25/Assumptions!C6 -> 0.73984127 | E25: =C25-Pricing!C19 -> -185.77135 | F25: =IF(B25>Assumptions!C7,"DISCOUNT",IF(B25<Assumptions!C7,"PREMIUM","PAR")) -> DISCOUNT | G25: =Pricing!C19*(1-'Risk Metrics'!C15*(0.03)) -> 923.31338
B26: =+Assumptions!C14+0.035 -> 0.095 | C26: =IFERROR(Assumptions!C6*Assumptions!C7/Assumptions!C9*(1-(1+((Assumptions!C14+0.035)/Assumptions!C9))^(-ROUND(Assumptions!C8*Assumptions!C9,0)))/(((Assumptions!C14+0.035)/Assumptions!C9))+Assumptions!C6*(1+((Assumptions!C14+0.035)/Assumptions!C9))^(-ROUND(Assumptions!C8*Assumptions!C9,0)),ROUND(Assumptions!C8*Assumptions!C9,0)*Assumptions!C6*Assumptions!C7/Assumptions!C9+Assumptions!C6) -> 713.55995 | D26: =C26/Assumptions!C6 -> 0.71355995 | E26: =C26-Pricing!C19 -> -212.05268 | F26: =IF(B26>Assumptions!C7,"DISCOUNT",IF(B26<Assumptions!C7,"PREMIUM","PAR")) -> DISCOUNT | G26: =Pricing!C19*(1-'Risk Metrics'!C15*(0.035)) -> 922.93017
B27: =+Assumptions!C14+0.04 -> 0.1 | C27: =IFERROR(Assumptions!C6*Assumptions!C7/Assumptions!C9*(1-(1+((Assumptions!C14+0.04)/Assumptions!C9))^(-ROUND(Assumptions!C8*Assumptions!C9,0)))/(((Assumptions!C14+0.04)/Assumptions!C9))+Assumptions!C6*(1+((Assumptions!C14+0.04)/Assumptions!C9))^(-ROUND(Assumptions!C8*Assumptions!C9,0)),ROUND(Assumptions!C8*Assumptions!C9,0)*Assumptions!C6*Assumptions!C7/Assumptions!C9+Assumptions!C6) -> 688.44474 | D27: =C27/Assumptions!C6 -> 0.68844474 | E27: =C27-Pricing!C19 -> -237.16788 | F27: =IF(B27>Assumptions!C7,"DISCOUNT",IF(B27<Assumptions!C7,"PREMIUM","PAR")) -> DISCOUNT | G27: =Pricing!C19*(1-'Risk Metrics'!C15*(0.04)) -> 922.54696
B28: =+Assumptions!C14+0.045 -> 0.105 | C28: =IFERROR(Assumptions!C6*Assumptions!C7/Assumptions!C9*(1-(1+((Assumptions!C14+0.045)/Assumptions!C9))^(-ROUND(Assumptions!C8*Assumptions!C9,0)))/(((Assumptions!C14+0.045)/Assumptions!C9))+Assumptions!C6*(1+((Assumptions!C14+0.045)/Assumptions!C9))^(-ROUND(Assumptions!C8*Assumptions!C9,0)),ROUND(Assumptions!C8*Assumptions!C9,0)*Assumptions!C6*Assumptions!C7/Assumptions!C9+Assumptions!C6) -> 664.43888 | D28: =C28/Assumptions!C6 -> 0.66443888 | E28: =C28-Pricing!C19 -> -261.17375 | F28: =IF(B28>Assumptions!C7,"DISCOUNT",IF(B28<Assumptions!C7,"PREMIUM","PAR")) -> DISCOUNT | G28: =Pricing!C19*(1-'Risk Metrics'!C15*(0.045)) -> 922.16375
B29: =+Assumptions!C14+0.05 -> 0.11 | C29: =IFERROR(Assumptions!C6*Assumptions!C7/Assumptions!C9*(1-(1+((Assumptions!C14+0.05)/Assumptions!C9))^(-ROUND(Assumptions!C8*Assumptions!C9,0)))/(((Assumptions!C14+0.05)/Assumptions!C9))+Assumptions!C6*(1+((Assumptions!C14+0.05)/Assumptions!C9))^(-ROUND(Assumptions!C8*Assumptions!C9,0)),ROUND(Assumptions!C8*Assumptions!C9,0)*Assumptions!C6*Assumptions!C7/Assumptions!C9+Assumptions!C6) -> 641.48853 | D29: =C29/Assumptions!C6 -> 0.64148853 | E29: =C29-Pricing!C19 -> -284.1241 | F29: =IF(B29>Assumptions!C7,"DISCOUNT",IF(B29<Assumptions!C7,"PREMIUM","PAR")) -> DISCOUNT | G29: =Pricing!C19*(1-'Risk Metrics'!C15*(0.05)) -> 921.78054
B30: =+Assumptions!C14+0.055 -> 0.115 | C30: =IFERROR(Assumptions!C6*Assumptions!C7/Assumptions!C9*(1-(1+((Assumptions!C14+0.055)/Assumptions!C9))^(-ROUND(Assumptions!C8*Assumptions!C9,0)))/(((Assumptions!C14+0.055)/Assumptions!C9))+Assumptions!C6*(1+((Assumptions!C14+0.055)/Assumptions!C9))^(-ROUND(Assumptions!C8*Assumptions!C9,0)),ROUND(Assumptions!C8*Assumptions!C9,0)*Assumptions!C6*Assumptions!C7/Assumptions!C9+Assumptions!C6) -> 619.54263 | D30: =C30/Assumptions!C6 -> 0.61954263 | E30: =C30-Pricing!C19 -> -306.07 | F30: =IF(B30>Assumptions!C7,"DISCOUNT",IF(B30<Assumptions!C7,"PREMIUM","PAR")) -> DISCOUNT | G30: =Pricing!C19*(1-'Risk Metrics'!C15*(0.055)) -> 921.39733
B31: =+Assumptions!C14+0.06 -> 0.12 | C31: =IFERROR(Assumptions!C6*Assumptions!C7/Assumptions!C9*(1-(1+((Assumptions!C14+0.06)/Assumptions!C9))^(-ROUND(Assumptions!C8*Assumptions!C9,0)))/(((Assumptions!C14+0.06)/Assumptions!C9))+Assumptions!C6*(1+((Assumptions!C14+0.06)/Assumptions!C9))^(-ROUND(Assumptions!C8*Assumptions!C9,0)),ROUND(Assumptions!C8*Assumptions!C9,0)*Assumptions!C6*Assumptions!C7/Assumptions!C9+Assumptions!C6) -> 598.55276 | D31: =C31/Assumptions!C6 -> 0.59855276 | E31: =C31-Pricing!C19 -> -327.05987 | F31: =IF(B31>Assumptions!C7,"DISCOUNT",IF(B31<Assumptions!C7,"PREMIUM","PAR")) -> DISCOUNT | G31: =Pricing!C19*(1-'Risk Metrics'!C15*(0.06)) -> 921.01413
B32: =+Assumptions!C14+0.065 -> 0.125 | C32: =IFERROR(Assumptions!C6*Assumptions!C7/Assumptions!C9*(1-(1+((Assumptions!C14+0.065)/Assumptions!C9))^(-ROUND(Assumptions!C8*Assumptions!C9,0)))/(((Assumptions!C14+0.065)/Assumptions!C9))+Assumptions!C6*(1+((Assumptions!C14+0.065)/Assumptions!C9))^(-ROUND(Assumptions!C8*Assumptions!C9,0)),ROUND(Assumptions!C8*Assumptions!C9,0)*Assumptions!C6*Assumptions!C7/Assumptions!C9+Assumptions!C6) -> 578.47298 | D32: =C32/Assumptions!C6 -> 0.57847298 | E32: =C32-Pricing!C19 -> -347.13965 | F32: =IF(B32>Assumptions!C7,"DISCOUNT",IF(B32<Assumptions!C7,"PREMIUM","PAR")) -> DISCOUNT | G32: =Pricing!C19*(1-'Risk Metrics'!C15*(0.065)) -> 920.63092
B33: =+Assumptions!C14+0.07 -> 0.13 | C33: =IFERROR(Assumptions!C6*Assumptions!C7/Assumptions!C9*(1-(1+((Assumptions!C14+0.07)/Assumptions!C9))^(-ROUND(Assumptions!C8*Assumptions!C9,0)))/(((Assumptions!C14+0.07)/Assumptions!C9))+Assumptions!C6*(1+((Assumptions!C14+0.07)/Assumptions!C9))^(-ROUND(Assumptions!C8*Assumptions!C9,0)),ROUND(Assumptions!C8*Assumptions!C9,0)*Assumptions!C6*Assumptions!C7/Assumptions!C9+Assumptions!C6) -> 559.25971 | D33: =C33/Assumptions!C6 -> 0.55925971 | E33: =C33-Pricing!C19 -> -366.35292 | F33: =IF(B33>Assumptions!C7,"DISCOUNT",IF(B33<Assumptions!C7,"PREMIUM","PAR")) -> DISCOUNT | G33: =Pricing!C19*(1-'Risk Metrics'!C15*(0.07)) -> 920.24771
B39: Yellow row = current market yield. Status based on yield vs coupon rate: yield>coupon→Discount, yield<coupon→Premium.

Sheet Scenario Analysis
A1: Yariverse Bank | Fixed Income Analytics | Scenario Analysis
A2: SCENARIO ANALYSIS : True Reprice vs. Duration vs. Duration+Convexity Approximations
B4: Shock (bps) | C4: Shock (%) | D4: True Repriced ($) | E4: Dur-Only ($) | F4: Dur-Only Err ($) | G4: Dur+Conv ($) | H4: Dur+Conv Err ($)
B5: -300 | C5: -0.03 | D5: =IFERROR(Assumptions!C6*Assumptions!C7/Assumptions!C9*(1-(1+((Assumptions!C14-0.03)/Assumptions!C9))^(-ROUND(Assumptions!C8*Assumptions!C9,0)))/(((Assumptions!C14-0.03)/Assumptions!C9))+Assumptions!C6*(1+((Assumptions!C14-0.03)/Assumptions!C9))^(-ROUND(Assumptions!C8*Assumptions!C9,0)),ROUND(Assumptions!C8*Assumptions!C9,0)*Assumptions!C6*Assumptions!C7/Assumptions!C9+Assumptions!C6) -> 1171.6864 | E5: =Pricing!C19*(1-'Risk Metrics'!C15*(-0.03)) -> 927.91188 | F5: =E5-D5 -> -243.77451 | G5: =Pricing!C19*(1-'Risk Metrics'!C15*(-0.03)+0.5*'Risk Metrics'!C21*(-0.03)^2) -> 927.91702 | H5: =G5-D5 -> -243.76936
B6: -275 | C6: -0.0275 | D6: =IFERROR(Assumptions!C6*Assumptions!C7/Assumptions!C9*(1-(1+((Assumptions!C14-0.0275)/Assumptions!C9))^(-ROUND(Assumptions!C8*Assumptions!C9,0)))/(((Assumptions!C14-0.0275)/Assumptions!C9))+Assumptions!C6*(1+((Assumptions!C14-0.0275)/Assumptions!C9))^(-ROUND(Assumptions!C8*Assumptions!C9,0)),ROUND(Assumptions!C8*Assumptions!C9,0)*Assumptions!C6*Assumptions!C7/Assumptions!C9+Assumptions!C6) -> 1148.3907 | E6: =Pricing!C19*(1-'Risk Metrics'!C15*(-0.0275)) -> 927.72027 | F6: =E6-D6 -> -220.6704 | G6: =Pricing!C19*(1-'Risk Metrics'!C15*(-0.0275)+0.5*'Risk Metrics'!C21*(-0.0275)^2) -> 927.7246 | H6: =G6-D6 -> -220.66607
B7: -250 | C7: -0.025 | D7: =IFERROR(Assumptions!C6*Assumptions!C7/Assumptions!C9*(1-(1+((Assumptions!C14-0.025)/Assumptions!C9))^(-ROUND(Assumptions!C8*Assumptions!C9,0)))/(((Assumptions!C14-0.025)/Assumptions!C9))+Assumptions!C6*(1+((Assumptions!C14-0.025)/Assumptions!C9))^(-ROUND(Assumptions!C8*Assumptions!C9,0)),ROUND(Assumptions!C8*Assumptions!C9,0)*Assumptions!C6*Assumptions!C7/Assumptions!C9+Assumptions!C6) -> 1125.6466 | E7: =Pricing!C19*(1-'Risk Metrics'!C15*(-0.025)) -> 927.52867 | F7: =E7-D7 -> -198.11794 | G7: =Pricing!C19*(1-'Risk Metrics'!C15*(-0.025)+0.5*'Risk Metrics'!C21*(-0.025)^2) -> 927.53224 | H7: =G7-D7 -> -198.11437
B8: -225 | C8: -0.0225 | D8: =IFERROR(Assumptions!C6*Assumptions!C7/Assumptions!C9*(1-(1+((Assumptions!C14-0.0225)/Assumptions!C9))^(-ROUND(Assumptions!C8*Assumptions!C9,0)))/(((Assumptions!C14-0.0225)/Assumptions!C9))+Assumptions!C6*(1+((Assumptions!C14-0.0225)/Assumptions!C9))^(-ROUND(Assumptions!C8*Assumptions!C9,0)),ROUND(Assumptions!C8*Assumptions!C9,0)*Assumptions!C6*Assumptions!C7/Assumptions!C9+Assumptions!C6) -> 1103.44 | E8: =Pricing!C19*(1-'Risk Metrics'!C15*(-0.0225)) -> 927.33706 | F8: =E8-D8 -> -176.10297 | G8: =Pricing!C19*(1-'Risk Metrics'!C15*(-0.0225)+0.5*'Risk Metrics'!C21*(-0.0225)^2) -> 927.33996 | H8: =G8-D8 -> -176.10008
B9: -200 | C9: -0.02 | D9: =IFERROR(Assumptions!C6*Assumptions!C7/Assumptions!C9*(1-(1+((Assumptions!C14-0.02)/Assumptions!C9))^(-ROUND(Assumptions!C8*Assumptions!C9,0)))/(((Assumptions!C14-0.02)/Assumptions!C9))+Assumptions!C6*(1+((Assumptions!C14-0.02)/Assumptions!C9))^(-ROUND(Assumptions!C8*Assumptions!C9,0)),ROUND(Assumptions!C8*Assumptions!C9,0)*Assumptions!C6*Assumptions!C7/Assumptions!C9+Assumptions!C6) -> 1081.7572 | E9: =Pricing!C19*(1-'Risk Metrics'!C15*(-0.02)) -> 927.14546 | F9: =E9-D9 -> -154.61171 | G9: =Pricing!C19*(1-'Risk Metrics'!C15*(-0.02)+0.5*'Risk Metrics'!C21*(-0.02)^2) -> 927.14775 | H9: =G9-D9 -> -154.60942
B10: -175 | C10: -0.0175 | D10: =IFERROR(Assumptions!C6*Assumptions!C7/Assumptions!C9*(1-(1+((Assumptions!C14-0.0175)/Assumptions!C9))^(-ROUND(Assumptions!C8*Assumptions!C9,0)))/(((Assumptions!C14-0.0175)/Assumptions!C9))+Assumptions!C6*(1+((Assumptions!C14-0.0175)/Assumptions!C9))^(-ROUND(Assumptions!C8*Assumptions!C9,0)),ROUND(Assumptions!C8*Assumptions!C9,0)*Assumptions!C6*Assumptions!C7/Assumptions!C9+Assumptions!C6) -> 1060.5846 | E10: =Pricing!C19*(1-'Risk Metrics'!C15*(-0.0175)) -> 926.95385 | F10: =E10-D10 -> -133.63074 | G10: =Pricing!C19*(1-'Risk Metrics'!C15*(-0.0175)+0.5*'Risk Metrics'!C21*(-0.0175)^2) -> 926.95561 | H10: =G10-D10 -> -133.62899
B11: -150 | C11: -0.015 | D11: =IFERROR(Assumptions!C6*Assumptions!C7/Assumptions!C9*(1-(1+((Assumptions!C14-0.015)/Assumptions!C9))^(-ROUND(Assumptions!C8*Assumptions!C9,0)))/(((Assumptions!C14-0.015)/Assumptions!C9))+Assumptions!C6*(1+((Assumptions!C14-0.015)/Assumptions!C9))^(-ROUND(Assumptions!C8*Assumptions!C9,0)),ROUND(Assumptions!C8*Assumptions!C9,0)*Assumptions!C6*Assumptions!C7/Assumptions!C9+Assumptions!C6) -> 1039.9093 | E11: =Pricing!C19*(1-'Risk Metrics'!C15*(-0.015)) -> 926.76225 | F11: =E11-D11 -> -113.14703 | G11: =Pricing!C19*(1-'Risk Metrics'!C15*(-0.015)+0.5*'Risk Metrics'!C21*(-0.015)^2) -> 926.76354 | H11: =G11-D11 -> -113.14574
B12: -125 | C12: -0.0125 | D12: =IFERROR(Assumptions!C6*Assumptions!C7/Assumptions!C9*(1-(1+((Assumptions!C14-0.0125)/Assumptions!C9))^(-ROUND(Assumptions!C8*Assumptions!C9,0)))/(((Assumptions!C14-0.0125)/Assumptions!C9))+Assumptions!C6*(1+((Assumptions!C14-0.0125)/Assumptions!C9))^(-ROUND(Assumptions!C8*Assumptions!C9,0)),ROUND(Assumptions!C8*Assumptions!C9,0)*Assumptions!C6*Assumptions!C7/Assumptions!C9+Assumptions!C6) -> 1019.7185 | E12: =Pricing!C19*(1-'Risk Metrics'!C15*(-0.0125)) -> 926.57065 | F12: =E12-D12 -> -93.147884 | G12: =Pricing!C19*(1-'Risk Metrics'!C15*(-0.0125)+0.5*'Risk Metrics'!C21*(-0.0125)^2) -> 926.57154 | H12: =G12-D12 -> -93.146991
B13: -100 | C13: -0.01 | D13: =IFERROR(Assumptions!C6*Assumptions!C7/Assumptions!C9*(1-(1+((Assumptions!C14-0.01)/Assumptions!C9))^(-ROUND(Assumptions!C8*Assumptions!C9,0)))/(((Assumptions!C14-0.01)/Assumptions!C9))+Assumptions!C6*(1+((Assumptions!C14-0.01)/Assumptions!C9))^(-ROUND(Assumptions!C8*Assumptions!C9,0)),ROUND(Assumptions!C8*Assumptions!C9,0)*Assumptions!C6*Assumptions!C7/Assumptions!C9+Assumptions!C6) -> 1000 | E13: =Pricing!C19*(1-'Risk Metrics'!C15*(-0.01)) -> 926.37904 | F13: =E13-D13 -> -73.620958 | G13: =Pricing!C19*(1-'Risk Metrics'!C15*(-0.01)+0.5*'Risk Metrics'!C21*(-0.01)^2) -> 926.37961 | H13: =G13-D13 -> -73.620386
B14: -75 | C14: -0.0075 | D14: =IFERROR(Assumptions!C6*Assumptions!C7/Assumptions!C9*(1-(1+((Assumptions!C14-0.0075)/Assumptions!C9))^(-ROUND(Assumptions!C8*Assumptions!C9,0)))/(((Assumptions!C14-0.0075)/Assumptions!C9))+Assumptions!C6*(1+((Assumptions!C14-0.0075)/Assumptions!C9))^(-ROUND(Assumptions!C8*Assumptions!C9,0)),ROUND(Assumptions!C8*Assumptions!C9,0)*Assumptions!C6*Assumptions!C7/Assumptions!C9+Assumptions!C6) -> 980.74168 | E14: =Pricing!C19*(1-'Risk Metrics'!C15*(-0.0075)) -> 926.18744 | F14: =E14-D14 -> -54.554237 | G14: =Pricing!C19*(1-'Risk Metrics'!C15*(-0.0075)+0.5*'Risk Metrics'!C21*(-0.0075)^2) -> 926.18776 | H14: =G14-D14 -> -54.553916
B15: -50 | C15: -0.005 | D15: =IFERROR(Assumptions!C6*Assumptions!C7/Assumptions!C9*(1-(1+((Assumptions!C14-0.005)/Assumptions!C9))^(-ROUND(Assumptions!C8*Assumptions!C9,0)))/(((Assumptions!C14-0.005)/Assumptions!C9))+Assumptions!C6*(1+((Assumptions!C14-0.005)/Assumptions!C9))^(-ROUND(Assumptions!C8*Assumptions!C9,0)),ROUND(Assumptions!C8*Assumptions!C9,0)*Assumptions!C6*Assumptions!C7/Assumptions!C9+Assumptions!C6) -> 961.93187 | E15: =Pricing!C19*(1-'Risk Metrics'!C15*(-0.005)) -> 925.99583 | F15: =E15-D15 -> -35.936036 | G15: =Pricing!C19*(1-'Risk Metrics'!C15*(-0.005)+0.5*'Risk Metrics'!C21*(-0.005)^2) -> 925.99598 | H15: =G15-D15 -> -35.935893
B16: -25 | C16: -0.0025 | D16: =IFERROR(Assumptions!C6*Assumptions!C7/Assumptions!C9*(1-(1+((Assumptions!C14-0.0025)/Assumptions!C9))^(-ROUND(Assumptions!C8*Assumptions!C9,0)))/(((Assumptions!C14-0.0025)/Assumptions!C9))+Assumptions!C6*(1+((Assumptions!C14-0.0025)/Assumptions!C9))^(-ROUND(Assumptions!C8*Assumptions!C9,0)),ROUND(Assumptions!C8*Assumptions!C9,0)*Assumptions!C6*Assumptions!C7/Assumptions!C9+Assumptions!C6) -> 943.55921 | E16: =Pricing!C19*(1-'Risk Metrics'!C15*(-0.0025)) -> 925.80423 | F16: =E16-D16 -> -17.754979 | G16: =Pricing!C19*(1-'Risk Metrics'!C15*(-0.0025)+0.5*'Risk Metrics'!C21*(-0.0025)^2) -> 925.80427 | H16: =G16-D16 -> -17.754943
